Traceback (most recent call last):
  File "/Users/caballero/opt/anaconda3/envs/teaching/lib/python3.10/site-packages/jupyter_cache/executors/utils.py", line 51, in single_nb_execution
    executenb(
  File "/Users/caballero/opt/anaconda3/envs/teaching/lib/python3.10/site-packages/nbclient/client.py", line 1204, in execute
    return NotebookClient(nb=nb, resources=resources, km=km, **kwargs).execute()
  File "/Users/caballero/opt/anaconda3/envs/teaching/lib/python3.10/site-packages/nbclient/util.py", line 84, in wrapped
    return just_run(coro(*args, **kwargs))
  File "/Users/caballero/opt/anaconda3/envs/teaching/lib/python3.10/site-packages/nbclient/util.py", line 62, in just_run
    return loop.run_until_complete(coro)
  File "/Users/caballero/opt/anaconda3/envs/teaching/lib/python3.10/asyncio/base_events.py", line 646, in run_until_complete
    return future.result()
  File "/Users/caballero/opt/anaconda3/envs/teaching/lib/python3.10/site-packages/nbclient/client.py", line 663, in async_execute
    await self.async_execute_cell(
  File "/Users/caballero/opt/anaconda3/envs/teaching/lib/python3.10/site-packages/nbclient/client.py", line 965, in async_execute_cell
    await self._check_raise_for_error(cell, cell_index, exec_reply)
  File "/Users/caballero/opt/anaconda3/envs/teaching/lib/python3.10/site-packages/nbclient/client.py", line 862, in _check_raise_for_error
    raise CellExecutionError.from_cell_and_msg(cell, exec_reply_content)
nbclient.exceptions.CellExecutionError: An error occurred while executing the following cell:
------------------
from scipy.integrate import odeint

y0 = [179/360*2*np.pi,0]
t = np.linspace(0,10,N)

def PhysicalPendulum(y,t,g,l):
    
    theta = y[0]
    omega = y[1]
    dtheta_dt = omega
    domega_dt = -(g/l)*np.sin(theta) 
    
    return [dtheta_dt,domega_dt]

theta = odeint(PhysicalPendulum, y0, t, args = (g,l))

fig, ax1 = plt.subplots()

ax1.plot(t, theta[:,0])
ax1.plot(tpoints4, xpoints4[:,0])

plt.legend(['SciPy', 'RK4'], loc=1)
plt.xlabel('t')
plt.ylabel('theta(t)')
------------------

[0;31m---------------------------------------------------------------------------[0m
[0;31mNameError[0m                                 Traceback (most recent call last)
Input [0;32mIn [16][0m, in [0;36m<cell line: 15>[0;34m()[0m
[1;32m     11[0m     domega_dt [38;5;241m=[39m [38;5;241m-[39m(g[38;5;241m/[39ml)[38;5;241m*[39mnp[38;5;241m.[39msin(theta) 
[1;32m     13[0m     [38;5;28;01mreturn[39;00m [dtheta_dt,domega_dt]
[0;32m---> 15[0m theta [38;5;241m=[39m odeint(PhysicalPendulum, y0, t, args [38;5;241m=[39m ([43mg[49m,l))
[1;32m     17[0m fig, ax1 [38;5;241m=[39m plt[38;5;241m.[39msubplots()
[1;32m     19[0m ax1[38;5;241m.[39mplot(t, theta[:,[38;5;241m0[39m])

[0;31mNameError[0m: name 'g' is not defined
NameError: name 'g' is not defined

